[2023-08-18 09:35:41 +0000] [27156] [INFO] Starting gunicorn 21.2.0
[2023-08-18 09:35:41 +0000] [27156] [INFO] Listening at: http://0.0.0.0:8000 (27156)
[2023-08-18 09:35:41 +0000] [27156] [INFO] Using worker: sync
[2023-08-18 09:35:41 +0000] [27157] [INFO] Booting worker with pid: 27157
[2023-08-18 09:35:41 +0000] [27157] [ERROR] Exception in worker process
Traceback (most recent call last):
  File "/home/ubuntu/force_be/venv/lib/python3.10/site-packages/gunicorn/arbiter.py", line 609, in spawn_worker
    worker.init_process()
  File "/home/ubuntu/force_be/venv/lib/python3.10/site-packages/gunicorn/workers/base.py", line 134, in init_process
    self.load_wsgi()
  File "/home/ubuntu/force_be/venv/lib/python3.10/site-packages/gunicorn/workers/base.py", line 146, in load_wsgi
    self.wsgi = self.app.wsgi()
  File "/home/ubuntu/force_be/venv/lib/python3.10/site-packages/gunicorn/app/base.py", line 67, in wsgi
    self.callable = self.load()
  File "/home/ubuntu/force_be/venv/lib/python3.10/site-packages/gunicorn/app/wsgiapp.py", line 58, in load
    return self.load_wsgiapp()
  File "/home/ubuntu/force_be/venv/lib/python3.10/site-packages/gunicorn/app/wsgiapp.py", line 48, in load_wsgiapp
    return util.import_app(self.app_uri)
  File "/home/ubuntu/force_be/venv/lib/python3.10/site-packages/gunicorn/util.py", line 371, in import_app
    mod = importlib.import_module(module)
  File "/usr/lib/python3.10/importlib/__init__.py", line 126, in import_module
    return _bootstrap._gcd_import(name[level:], package, level)
  File "<frozen importlib._bootstrap>", line 1050, in _gcd_import
  File "<frozen importlib._bootstrap>", line 1027, in _find_and_load
  File "<frozen importlib._bootstrap>", line 992, in _find_and_load_unlocked
  File "<frozen importlib._bootstrap>", line 241, in _call_with_frames_removed
  File "<frozen importlib._bootstrap>", line 1050, in _gcd_import
  File "<frozen importlib._bootstrap>", line 1027, in _find_and_load
  File "<frozen importlib._bootstrap>", line 1004, in _find_and_load_unlocked
ModuleNotFoundError: No module named 'config'
[2023-08-18 09:35:41 +0000] [27157] [INFO] Worker exiting (pid: 27157)
[2023-08-18 09:35:41 +0000] [27156] [ERROR] Worker (pid:27157) exited with code 3
[2023-08-18 09:35:41 +0000] [27156] [ERROR] Shutting down: Master
[2023-08-18 09:35:41 +0000] [27156] [ERROR] Reason: Worker failed to boot.
