[2023-08-17 09:50:56 +0000] [21306] [INFO] Starting gunicorn 21.2.0
[2023-08-17 09:50:56 +0000] [21306] [INFO] Listening at: http://0.0.0.0:8000 (21306)
[2023-08-17 09:50:56 +0000] [21306] [INFO] Using worker: sync
[2023-08-17 09:50:56 +0000] [21307] [INFO] Booting worker with pid: 21307
[2023-08-17 09:50:56 +0000] [21307] [ERROR] Exception in worker process
Traceback (most recent call last):
  File "/home/ubuntu/force_be/venv/lib/python3.10/site-packages/gunicorn/arbiter.py", line 609, in spawn_worker
    worker.init_process()
  File "/home/ubuntu/force_be/venv/lib/python3.10/site-packages/gunicorn/workers/base.py", line 134, in init_process
    self.load_wsgi()
  File "/home/ubuntu/force_be/venv/lib/python3.10/site-packages/gunicorn/workers/base.py", line 146, in load_wsgi
    self.wsgi = self.app.wsgi()
  File "/home/ubuntu/force_be/venv/lib/python3.10/site-packages/gunicorn/app/base.py", line 67, in wsgi
    self.callable = self.load()
  File "/home/ubuntu/force_be/venv/lib/python3.10/site-packages/gunicorn/app/wsgiapp.py", line 58, in load
    return self.load_wsgiapp()
  File "/home/ubuntu/force_be/venv/lib/python3.10/site-packages/gunicorn/app/wsgiapp.py", line 48, in load_wsgiapp
    return util.import_app(self.app_uri)
  File "/home/ubuntu/force_be/venv/lib/python3.10/site-packages/gunicorn/util.py", line 371, in import_app
    mod = importlib.import_module(module)
  File "/usr/lib/python3.10/importlib/__init__.py", line 126, in import_module
    return _bootstrap._gcd_import(name[level:], package, level)
  File "<frozen importlib._bootstrap>", line 1050, in _gcd_import
  File "<frozen importlib._bootstrap>", line 1027, in _find_and_load
  File "<frozen importlib._bootstrap>", line 992, in _find_and_load_unlocked
  File "<frozen importlib._bootstrap>", line 241, in _call_with_frames_removed
  File "<frozen importlib._bootstrap>", line 1050, in _gcd_import
  File "<frozen importlib._bootstrap>", line 1027, in _find_and_load
  File "<frozen importlib._bootstrap>", line 1004, in _find_and_load_unlocked
ModuleNotFoundError: No module named 'config'
[2023-08-17 09:50:56 +0000] [21307] [INFO] Worker exiting (pid: 21307)
[2023-08-17 09:50:56 +0000] [21306] [ERROR] Worker (pid:21307) exited with code 3
[2023-08-17 09:50:56 +0000] [21306] [ERROR] Shutting down: Master
[2023-08-17 09:50:56 +0000] [21306] [ERROR] Reason: Worker failed to boot.
[2023-08-17 09:51:21 +0000] [21308] [INFO] Starting gunicorn 21.2.0
[2023-08-17 09:51:21 +0000] [21308] [INFO] Listening at: http://0.0.0.0:8000 (21308)
[2023-08-17 09:51:21 +0000] [21308] [INFO] Using worker: sync
[2023-08-17 09:51:21 +0000] [21309] [INFO] Booting worker with pid: 21309
[2023-08-17 09:51:21 +0000] [21309] [ERROR] Exception in worker process
Traceback (most recent call last):
  File "/home/ubuntu/force_be/venv/lib/python3.10/site-packages/gunicorn/arbiter.py", line 609, in spawn_worker
    worker.init_process()
  File "/home/ubuntu/force_be/venv/lib/python3.10/site-packages/gunicorn/workers/base.py", line 134, in init_process
    self.load_wsgi()
  File "/home/ubuntu/force_be/venv/lib/python3.10/site-packages/gunicorn/workers/base.py", line 146, in load_wsgi
    self.wsgi = self.app.wsgi()
  File "/home/ubuntu/force_be/venv/lib/python3.10/site-packages/gunicorn/app/base.py", line 67, in wsgi
    self.callable = self.load()
  File "/home/ubuntu/force_be/venv/lib/python3.10/site-packages/gunicorn/app/wsgiapp.py", line 58, in load
    return self.load_wsgiapp()
  File "/home/ubuntu/force_be/venv/lib/python3.10/site-packages/gunicorn/app/wsgiapp.py", line 48, in load_wsgiapp
    return util.import_app(self.app_uri)
  File "/home/ubuntu/force_be/venv/lib/python3.10/site-packages/gunicorn/util.py", line 371, in import_app
    mod = importlib.import_module(module)
  File "/usr/lib/python3.10/importlib/__init__.py", line 126, in import_module
    return _bootstrap._gcd_import(name[level:], package, level)
  File "<frozen importlib._bootstrap>", line 1050, in _gcd_import
  File "<frozen importlib._bootstrap>", line 1027, in _find_and_load
  File "<frozen importlib._bootstrap>", line 992, in _find_and_load_unlocked
  File "<frozen importlib._bootstrap>", line 241, in _call_with_frames_removed
  File "<frozen importlib._bootstrap>", line 1050, in _gcd_import
  File "<frozen importlib._bootstrap>", line 1027, in _find_and_load
  File "<frozen importlib._bootstrap>", line 1004, in _find_and_load_unlocked
ModuleNotFoundError: No module named 'config'
[2023-08-17 09:51:21 +0000] [21309] [INFO] Worker exiting (pid: 21309)
[2023-08-17 09:51:21 +0000] [21308] [ERROR] Worker (pid:21309) exited with code 3
[2023-08-17 09:51:21 +0000] [21308] [ERROR] Shutting down: Master
[2023-08-17 09:51:21 +0000] [21308] [ERROR] Reason: Worker failed to boot.
Traceback (most recent call last):
  File "/home/ubuntu/force_be/config/wsgi.py", line 16, in <module>
    application = get_wsgi_application()
  File "/home/ubuntu/force_be/venv/lib/python3.10/site-packages/django/core/wsgi.py", line 12, in get_wsgi_application
    django.setup(set_prefix=False)
  File "/home/ubuntu/force_be/venv/lib/python3.10/site-packages/django/__init__.py", line 19, in setup
    configure_logging(settings.LOGGING_CONFIG, settings.LOGGING)
  File "/home/ubuntu/force_be/venv/lib/python3.10/site-packages/django/conf/__init__.py", line 102, in __getattr__
    self._setup(name)
  File "/home/ubuntu/force_be/venv/lib/python3.10/site-packages/django/conf/__init__.py", line 89, in _setup
    self._wrapped = Settings(settings_module)
  File "/home/ubuntu/force_be/venv/lib/python3.10/site-packages/django/conf/__init__.py", line 217, in __init__
    mod = importlib.import_module(self.SETTINGS_MODULE)
  File "/usr/lib/python3.10/importlib/__init__.py", line 126, in import_module
    return _bootstrap._gcd_import(name[level:], package, level)
  File "<frozen importlib._bootstrap>", line 1050, in _gcd_import
  File "<frozen importlib._bootstrap>", line 1027, in _find_and_load
  File "<frozen importlib._bootstrap>", line 992, in _find_and_load_unlocked
  File "<frozen importlib._bootstrap>", line 241, in _call_with_frames_removed
  File "<frozen importlib._bootstrap>", line 1050, in _gcd_import
  File "<frozen importlib._bootstrap>", line 1027, in _find_and_load
  File "<frozen importlib._bootstrap>", line 1004, in _find_and_load_unlocked
ModuleNotFoundError: No module named 'config'
Traceback (most recent call last):
  File "/home/ubuntu/force_be/config/wsgi.py", line 16, in <module>
    application = get_wsgi_application()
  File "/home/ubuntu/force_be/venv/lib/python3.10/site-packages/django/core/wsgi.py", line 12, in get_wsgi_application
    django.setup(set_prefix=False)
  File "/home/ubuntu/force_be/venv/lib/python3.10/site-packages/django/__init__.py", line 19, in setup
    configure_logging(settings.LOGGING_CONFIG, settings.LOGGING)
  File "/home/ubuntu/force_be/venv/lib/python3.10/site-packages/django/conf/__init__.py", line 102, in __getattr__
    self._setup(name)
  File "/home/ubuntu/force_be/venv/lib/python3.10/site-packages/django/conf/__init__.py", line 89, in _setup
    self._wrapped = Settings(settings_module)
  File "/home/ubuntu/force_be/venv/lib/python3.10/site-packages/django/conf/__init__.py", line 217, in __init__
    mod = importlib.import_module(self.SETTINGS_MODULE)
  File "/usr/lib/python3.10/importlib/__init__.py", line 126, in import_module
    return _bootstrap._gcd_import(name[level:], package, level)
  File "<frozen importlib._bootstrap>", line 1050, in _gcd_import
  File "<frozen importlib._bootstrap>", line 1027, in _find_and_load
  File "<frozen importlib._bootstrap>", line 992, in _find_and_load_unlocked
  File "<frozen importlib._bootstrap>", line 241, in _call_with_frames_removed
  File "<frozen importlib._bootstrap>", line 1050, in _gcd_import
  File "<frozen importlib._bootstrap>", line 1027, in _find_and_load
  File "<frozen importlib._bootstrap>", line 1004, in _find_and_load_unlocked
ModuleNotFoundError: No module named 'config'
